Internal Server Error: /users/login/
Traceback (most recent call last):
  File "/home/user/github/know_your/server/.env/local/lib/python2.7/site-packages/django/core/handlers/base.py", line 114, in get_response
    response = wrapped_callback(request, *callback_args, **callback_kwargs)
  File "/home/user/github/know_your/server/.env/local/lib/python2.7/site-packages/django/views/decorators/csrf.py", line 57, in wrapped_view
    return view_func(*args, **kwargs)
  File "/home/user/github/know_your/server/.env/local/lib/python2.7/site-packages/django/views/generic/base.py", line 69, in view
    return self.dispatch(request, *args, **kwargs)
  File "/home/user/github/know_your/server/.env/local/lib/python2.7/site-packages/rest_framework/views.py", line 403, in dispatch
    response = self.handle_exception(exc)
  File "/home/user/github/know_your/server/.env/local/lib/python2.7/site-packages/rest_framework/views.py", line 400, in dispatch
    response = handler(request, *args, **kwargs)
  File "/home/user/github/know_your/server/.env/local/lib/python2.7/site-packages/rest_framework/decorators.py", line 50, in handler
    return func(*args, **kwargs)
  File "/home/user/github/know_your/server/app/users/views.py", line 13, in login
    key = form.get_token()
  File "/home/user/github/know_your/server/app/users/forms.py", line 38, in get_token
    return Token.objects.get(user__pk=self.user.pk).key
  File "/home/user/github/know_your/server/.env/local/lib/python2.7/site-packages/django/db/models/manager.py", line 151, in get
    return self.get_queryset().get(*args, **kwargs)
  File "/home/user/github/know_your/server/.env/local/lib/python2.7/site-packages/django/db/models/query.py", line 307, in get
    self.model._meta.object_name)
DoesNotExist: Token matching query does not exist.
